Workbook

Sheet BAGACEIRAS
A1: PV | B1: Item | C1: OS/Peças | D1: Seq. | E1: Cliente | F1: Descrição | G1: Qtde. | H1: Prazo Fundido | I1: Pz Fundido Real | J1: Prazo Entrega | K1: Pz Entrega Real | L1: Dias Falta2 | M1: Indicador | N1: CONDIÇÃO | O1: Desenho Previsão | P1: Des. | Q1: OP1 | R1: OP2 | S1: OP3 | T1: OP4 | U1: OP5 | V1: OP6 | W1: OP7 | X1: Status Us. | Y1: Obs. | Z1: Plainar Facear | AA1: Serrar2 | AB1: Solda Dura2 | AC1: Encaixe / Furação | AD1: Acabam./ Inspeção
A2: 2199 | B2: 1 | C2: 956055 | D2: 1 | E2: Raizen Bonfim | F2: BAGACEIRA 78" | G2: 1 | H2: 46178 | I2: 46175 | J2: 46213 | K2: 46199 | L2: =Tabela1[[#This Row],[Prazo Entrega]]-TODAY() -> -17 | M2: =IF(L2<0,"ATRASADO",IF(L2<=15,"ATENÇÃO","NO PRAZO")) -> ATRASADO | N2: c/ usinagem | O2: OK | P2: OK | Q2: Perfil | R2: Serrar | S2: Encaixe | T2: Fur | U2: Acab | V2: Lib | X2: EXPEDIDO | Z2: 24 | AA2: =Tabela1[[#This Row],[Plainar Facear]]+1 -> 25 | AB2: n/a | AC2: =Tabela1[[#This Row],[Serrar2]]+1 -> 26 | AD2: =Tabela1[[#This Row],[Encaixe / Furação]]+1 -> 27
A3: 2199 | B3: 2 | C3: 956056 | D3: 1 | E3: Raizen Bonfim | F3: BAGACEIRA 78" | G3: 1 | H3: 46178 | I3: 46192 | J3: 46241 | L3: =Tabela1[[#This Row],[Prazo Entrega]]-TODAY() -> 11 | M3: =IF(L3<0,"ATRASADO",IF(L3<=15,"ATENÇÃO","NO PRAZO")) -> ATENÇÃO | N3: c/ usinagem | O3: OK | P3: OK | Q3: Perfil | R3: Serrar | S3: Encaixe | T3: Fur | U3: Acab | V3: Insp. | X3: EM INSPEÇÃO | Y3: RECUPERANDO | Z3: 24 | AA3: =Tabela1[[#This Row],[Plainar Facear]]+1 -> 25 | AB3: n/a | AC3: =Tabela1[[#This Row],[Serrar2]]+1 -> 26 | AD3: =Tabela1[[#This Row],[Encaixe / Furação]]+1 -> 27
A4: 2199 | B4: 3 | C4: 956057 | D4: 1 | E4: Raizen Bonfim | F4: BAGACEIRA 78" | G4: 1 | H4: 46178 | I4: 46192 | J4: 46241 | L4: =Tabela1[[#This Row],[Prazo Entrega]]-TODAY() -> 11 | M4: =IF(L4<0,"ATRASADO",IF(L4<=15,"ATENÇÃO","NO PRAZO")) -> ATENÇÃO | N4: c/ usinagem | O4: OK | P4: OK | Q4: Perfil | R4: Serrar | S4: Encaixe | T4: Fur | U4: Acab | V4: Insp. | X4: EM INSPEÇÃO | Y4: RECUPERANDO | Z4: 24 | AA4: =Tabela1[[#This Row],[Plainar Facear]]+1 -> 25 | AB4: n/a | AC4: =Tabela1[[#This Row],[Serrar2]]+1 -> 26 | AD4: =Tabela1[[#This Row],[Encaixe / Furação]]+1 -> 27
A5: 2199 | B5: 4 | C5: 956058 | D5: 1 | E5: Raizen Bonfim | F5: BAGACEIRA 78" | G5: 1 | H5: 46178 | I5: 46192 | J5: 46220 | K5: 46220 | L5: =Tabela1[[#This Row],[Prazo Entrega]]-TODAY() -> -10 | M5: =IF(L5<0,"ATRASADO",IF(L5<=15,"ATENÇÃO","NO PRAZO")) -> ATRASADO | N5: c/ usinagem | O5: OK | P5: OK | Q5: Perfil | R5: Serrar | S5: Encaixe | T5: Fur | U5: Acab | V5: Insp. | X5: EXPEDIDO | Z5: 24 | AA5: =Tabela1[[#This Row],[Plainar Facear]]+1 -> 25 | AB5: n/a | AC5: =Tabela1[[#This Row],[Serrar2]]+1 -> 26 | AD5: =Tabela1[[#This Row],[Encaixe / Furação]]+1 -> 27
A6: 2199 | B6: 5 | C6: 956059 | D6: 1 | E6: Raizen Bonfim | F6: BAGACEIRA 78" | G6: 1 | H6: 46178 | I6: 46192 | J6: 46220 | K6: 46220 | L6: =Tabela1[[#This Row],[Prazo Entrega]]-TODAY() -> -10 | M6: =IF(L6<0,"ATRASADO",IF(L6<=15,"ATENÇÃO","NO PRAZO")) -> ATRASADO | N6: c/ usinagem | O6: OK | P6: OK | Q6: Perfil | R6: Serrar | S6: Encaixe | T6: Fur | U6: Acab | V6: Insp. | X6: EXPEDIDO | Y6: RNC 13891 - EXCESSO DE SOBREMETAL | Z6: 24 | AA6: =Tabela1[[#This Row],[Plainar Facear]]+1 -> 25 | AB6: n/a | AC6: =Tabela1[[#This Row],[Serrar2]]+1 -> 26 | AD6: =Tabela1[[#This Row],[Encaixe / Furação]]+1 -> 27
A7: 2199 | B7: 6 | C7: 956060 | D7: 1 | E7: Raizen Bonfim | F7: BAGACEIRA 78" | G7: 1 | H7: 46178 | I7: 46188 | J7: 46220 | K7: 46220 | L7: =Tabela1[[#This Row],[Prazo Entrega]]-TODAY() -> -10 | M7: =IF(L7<0,"ATRASADO",IF(L7<=15,"ATENÇÃO","NO PRAZO")) -> ATRASADO | N7: c/ usinagem | O7: OK | P7: OK | Q7: Perfil | R7: Serrar | S7: Encaixe | T7: Fur | U7: Acab | V7: Insp. | X7: EXPEDIDO | Z7: 24 | AA7: =Tabela1[[#This Row],[Plainar Facear]]+1 -> 25 | AB7: n/a | AC7: =Tabela1[[#This Row],[Serrar2]]+1 -> 26 | AD7: =Tabela1[[#This Row],[Encaixe / Furação]]+1 -> 27
A8: 2199 | B8: 7 | C8: 956061 | D8: 1 | E8: Raizen Bonfim | F8: BAGACEIRA 78" | G8: 1 | H8: 46178 | I8: 46171 | J8: 46213 | K8: 46199 | L8: =Tabela1[[#This Row],[Prazo Entrega]]-TODAY() -> -17 | M8: =IF(L8<0,"ATRASADO",IF(L8<=15,"ATENÇÃO","NO PRAZO")) -> ATRASADO | N8: c/ usinagem | O8: OK | P8: OK | Q8: Perfil | R8: Serrar | S8: Encaixe | T8: Fur | U8: Acab | V8: Insp. | X8: EXPEDIDO | Z8: 23 | AA8: =Tabela1[[#This Row],[Plainar Facear]]+1 -> 24 | AB8: n/a | AC8: =Tabela1[[#This Row],[Serrar2]]+1 -> 25 | AD8: =Tabela1[[#This Row],[Encaixe / Furação]]+1 -> 26
A9: 2199 | B9: 8 | C9: 956062 | D9: 1 | E9: Raizen Bonfim | F9: BAGACEIRA 78" | G9: 1 | H9: 46178 | I9: 46171 | J9: 46213 | K9: 46199 | L9: =Tabela1[[#This Row],[Prazo Entrega]]-TODAY() -> -17 | M9: =IF(L9<0,"ATRASADO",IF(L9<=15,"ATENÇÃO","NO PRAZO")) -> ATRASADO | N9: c/ usinagem | O9: OK | P9: OK | Q9: Perfil | R9: Serrar | S9: Encaixe | T9: Fur | U9: Acab | V9: Insp. | X9: EXPEDIDO | Z9: 23 | AA9: =Tabela1[[#This Row],[Plainar Facear]]+1 -> 24 | AB9: n/a | AC9: =Tabela1[[#This Row],[Serrar2]]+1 -> 25 | AD9: =Tabela1[[#This Row],[Encaixe / Furação]]+1 -> 26
A10: 2199 | B10: 9 | C10: 956063 | D10: 1 | E10: Raizen Bonfim | F10: BAGACEIRA 78" | G10: 1 | H10: 46178 | I10: 46171 | J10: 46213 | K10: 46199 | L10: =Tabela1[[#This Row],[Prazo Entrega]]-TODAY() -> -17 | M10: =IF(L10<0,"ATRASADO",IF(L10<=15,"ATENÇÃO","NO PRAZO")) -> ATRASADO | N10: c/ usinagem | O10: OK | P10: OK | Q10: Perfil | R10: Serrar | S10: Encaixe | T10: Fur | U10: Acab | V10: Insp. | X10: EXPEDIDO | Z10: 23 | AA10: =Tabela1[[#This Row],[Plainar Facear]]+1 -> 24 | AB10: n/a | AC10: =Tabela1[[#This Row],[Serrar2]]+1 -> 25 | AD10: =Tabela1[[#This Row],[Encaixe / Furação]]+1 -> 26
A11: 2199 | B11: 10 | C11: 956064 | D11: 1 | E11: Raizen Bonfim | F11: BAGACEIRA 78" | G11: 1 | H11: 46178 | I11: 46171 | J11: 46213 | K11: 46199 | L11: =Tabela1[[#This Row],[Prazo Entrega]]-TODAY() -> -17 | M11: =IF(L11<0,"ATRASADO",IF(L11<=15,"ATENÇÃO","NO PRAZO")) -> ATRASADO | N11: c/ usinagem | O11: OK | P11: OK | Q11: Perfil | R11: Serrar | S11: Encaixe | T11: Fur | U11: Acab | V11: Insp. | X11: EXPEDIDO | Z11: 23 | AA11: =Tabela1[[#This Row],[Plainar Facear]]+1 -> 24 | AB11: n/a | AC11: =Tabela1[[#This Row],[Serrar2]]+1 -> 25 | AD11: =Tabela1[[#This Row],[Encaixe / Furação]]+1 -> 26
A12: 2201 | B12: 1 | C12: 1148030 | D12: 1 | E12: Raizen Costa Pinto | F12: BAGACEIRA 78" | G12: 1 | H12: 46178 | I12: 46192 | J12: 46220 | K12: 46220 | L12: =Tabela1[[#This Row],[Prazo Entrega]]-TODAY() -> -10 | M12: =IF(L12<0,"ATRASADO",IF(L12<=15,"ATENÇÃO","NO PRAZO")) -> ATRASADO | N12: c/ usinagem | O12: OK | P12: OK | Q12: Perfil | R12: Serrar | S12: Encaixe | T12: Fur | U12: Acab | V12: Insp. | X12: EXPEDIDO | Z12: 26 | AA12: =Tabela1[[#This Row],[Plainar Facear]]+1 -> 27 | AB12: n/a | AC12: =Tabela1[[#This Row],[Serrar2]]+1 -> 28 | AD12: =Tabela1[[#This Row],[Encaixe / Furação]]+1 -> 29
A13: 2201 | B13: 2 | C13: 1148031 | D13: 1 | E13: Raizen Costa Pinto | F13: BAGACEIRA 78" | G13: 1 | H13: 46178 | I13: 46192 | J13: 46220 | K13: 46220 | L13: =Tabela1[[#This Row],[Prazo Entrega]]-TODAY() -> -10 | M13: =IF(L13<0,"ATRASADO",IF(L13<=15,"ATENÇÃO","NO PRAZO")) -> ATRASADO | N13: c/ usinagem | O13: OK | P13: OK | Q13: Perfil | R13: Serrar | S13: Encaixe | T13: Fur | U13: Acab | V13: Insp. | X13: EXPEDIDO | Z13: 26 | AA13: =Tabela1[[#This Row],[Plainar Facear]]+1 -> 27 | AB13: n/a | AC13: =Tabela1[[#This Row],[Serrar2]]+1 -> 28 | AD13: =Tabela1[[#This Row],[Encaixe / Furação]]+1 -> 29
A14: 2201 | B14: 3 | C14: 1148032 | D14: 1 | E14: Raizen Costa Pinto | F14: BAGACEIRA 78" | G14: 1 | H14: 46178 | I14: 46189 | J14: 46220 | K14: 46220 | L14: =Tabela1[[#This Row],[Prazo Entrega]]-TODAY() -> -10 | M14: =IF(L14<0,"ATRASADO",IF(L14<=15,"ATENÇÃO","NO PRAZO")) -> ATRASADO | N14: c/ usinagem | O14: OK | P14: OK | Q14: Perfil | R14: Serrar | S14: Encaixe | T14: Fur | U14: Acab | V14: Insp. | X14: EXPEDIDO | Z14: 26 | AA14: =Tabela1[[#This Row],[Plainar Facear]]+1 -> 27 | AB14: n/a | AC14: =Tabela1[[#This Row],[Serrar2]]+1 -> 28 | AD14: =Tabela1[[#This Row],[Encaixe / Furação]]+1 -> 29
A15: 2199 | B15: 11 | C15: 956065 | D15: 1 | E15: Raizen Bonfim | F15: BAGACEIRA 78" | G15: 1 | H15: 46178 | I15: 46175 | J15: 46227 | K15: 46227 | L15: =Tabela1[[#This Row],[Prazo Entrega]]-TODAY() -> -3 | M15: =IF(L15<0,"ATRASADO",IF(L15<=15,"ATENÇÃO","NO PRAZO")) -> ATRASADO | N15: c/ usinagem | O15: OK | P15: OK | Q15: Perfil | R15: Serrar | S15: Encaixe | T15: Fur | U15: Acab | V15: Insp. | X15: EXPEDIDO | Y15: PARALISADO PARA SERRAR DENTES. LIBERADO SERRAR DIA 07/07/2026 NECESSARIO REUSINAR PERFIL | Z15: 26 | AA15: =Tabela1[[#This Row],[Plainar Facear]]+1 -> 27 | AB15: n/a | AC15: =Tabela1[[#This Row],[Serrar2]]+1 -> 28 | AD15: =Tabela1[[#This Row],[Encaixe / Furação]]+1 -> 29
A16: 2199 | B16: 12 | C16: 956066 | D16: 1 | E16: Raizen Bonfim | F16: BAGACEIRA 78" | G16: 1 | H16: 46178 | I16: 46175 | J16: 46220 | K16: 46220 | L16: =Tabela1[[#This Row],[Prazo Entrega]]-TODAY() -> -10 | M16: =IF(L16<0,"ATRASADO",IF(L16<=15,"ATENÇÃO","NO PRAZO")) -> ATRASADO | N16: c/ usinagem | O16: OK | P16: OK | Q16: Perfil | R16: Serrar | S16: Encaixe | T16: Fur | U16: Acab | V16: Insp. | X16: EXPEDIDO | Z16: 26 | AA16: =Tabela1[[#This Row],[Plainar Facear]]+1 -> 27 | AB16: n/a | AC16: =Tabela1[[#This Row],[Serrar2]]+1 -> 28 | AD16: =Tabela1[[#This Row],[Encaixe / Furação]]+1 -> 29
A17: 2201 | B17: 4 | C17: 1148033 | D17: 1 | E17: Raizen Costa Pinto | F17: BAGACEIRA 78" | G17: 1 | H17: 46185 | I17: 46175 | J17: 46213 | K17: 46199 | L17: =Tabela1[[#This Row],[Prazo Entrega]]-TODAY() -> -17 | M17: =IF(L17<0,"ATRASADO",IF(L17<=15,"ATENÇÃO","NO PRAZO")) -> ATRASADO | N17: c/ usinagem | O17: OK | P17: OK | Q17: Perfil | R17: Serrar | S17: Encaixe | T17: Fur | U17: Acab | V17: Insp. | X17: EXPEDIDO | Z17: 26 | AA17: =Tabela1[[#This Row],[Plainar Facear]]+1 -> 27 | AB17: n/a | AC17: =Tabela1[[#This Row],[Serrar2]]+1 -> 28 | AD17: =Tabela1[[#This Row],[Encaixe / Furação]]+1 -> 29
A18: 2201 | B18: 5 | C18: 1148034 | D18: 1 | E18: Raizen Costa Pinto | F18: BAGACEIRA 78" | G18: 1 | H18: 46185 | I18: 46175 | J18: 46213 | K18: 46199 | L18: =Tabela1[[#This Row],[Prazo Entrega]]-TODAY() -> -17 | M18: =IF(L18<0,"ATRASADO",IF(L18<=15,"ATENÇÃO","NO PRAZO")) -> ATRASADO | N18: c/ usinagem | O18: OK | P18: OK | Q18: Perfil | R18: Serrar | S18: Encaixe | T18: Fur | U18: Acab | V18: Insp. | X18: EXPEDIDO | Z18: 26 | AA18: =Tabela1[[#This Row],[Plainar Facear]]+1 -> 27 | AB18: n/a | AC18: =Tabela1[[#This Row],[Serrar2]]+1 -> 28 | AD18: =Tabela1[[#This Row],[Encaixe / Furação]]+1 -> 29
A19: 2201 | B19: 6 | C19: 1148035 | D19: 1 | E19: Raizen Costa Pinto | F19: BAGACEIRA 78" | G19: 1 | H19: 46185 | I19: 46175 | J19: 46213 | K19: 46199 | L19: =Tabela1[[#This Row],[Prazo Entrega]]-TODAY() -> -17 | M19: =IF(L19<0,"ATRASADO",IF(L19<=15,"ATENÇÃO","NO PRAZO")) -> ATRASADO | N19: c/ usinagem | O19: OK | P19: OK | Q19: Perfil | R19: Serrar | S19: Encaixe | T19: Fur | U19: Acab | V19: Insp. | X19: EXPEDIDO | Z19: 26 | AA19: =Tabela1[[#This Row],[Plainar Facear]]+1 -> 27 | AB19: n/a | AC19: =Tabela1[[#This Row],[Serrar2]]+1 -> 28 | AD19: =Tabela1[[#This Row],[Encaixe / Furação]]+1 -> 29
A20: 2201 | B20: 7 | C20: 1148036 | D20: 1 | E20: Raizen Costa Pinto | F20: BAGACEIRA 78" | G20: 1 | H20: 46185 | I20: 46206 | J20: 46220 | K20: 46220 | L20: =Tabela1[[#This Row],[Prazo Entrega]]-TODAY() -> -10 | M20: =IF(L20<0,"ATRASADO",IF(L20<=15,"ATENÇÃO","NO PRAZO")) -> ATRASADO | N20: c/ usinagem | O20: OK | P20: OK | Q20: Perfil | R20: Serrar | S20: Encaixe | T20: Fur | U20: Acab | V20: Insp. | X20: AG. COLETAR | Z20: 26 | AA20: =Tabela1[[#This Row],[Plainar Facear]]+1 -> 27 | AB20: n/a | AC20: =Tabela1[[#This Row],[Serrar2]]+1 -> 28 | AD20: =Tabela1[[#This Row],[Encaixe / Furação]]+1 -> 29
A21: 2201 | B21: 8 | C21: 1148037 | D21: 1 | E21: Raizen Costa Pinto | F21: BAGACEIRA 78" | G21: 1 | H21: 46185 | I21: 46206 | J21: 46227 | K21: 46227 | L21: =Tabela1[[#This Row],[Prazo Entrega]]-TODAY() -> -3 | M21: =IF(L21<0,"ATRASADO",IF(L21<=15,"ATENÇÃO","NO PRAZO")) -> ATRASADO | N21: c/ usinagem | O21: OK | P21: OK | Q21: Perfil | R21: Serrar | S21: Encaixe | T21: Fur | U21: Acab | V21: Insp. | X21: EXPEDIDO | Z21: 26 | AA21: =Tabela1[[#This Row],[Plainar Facear]]+1 -> 27 | AB21: n/a | AC21: =Tabela1[[#This Row],[Serrar2]]+1 -> 28 | AD21: =Tabela1[[#This Row],[Encaixe / Furação]]+1 -> 29
A22: 2203 | B22: 1 | C22: 958022 | D22: 1 | E22: Raizen Ipaussu | F22: BAGACEIRA 78" | G22: 1 | H22: 46185 | I22: 46189 | J22: 46227 | L22: =Tabela1[[#This Row],[Prazo Entrega]]-TODAY() -> -3 | M22: =IF(L22<0,"ATRASADO",IF(L22<=15,"ATENÇÃO","NO PRAZO")) -> ATRASADO | N22: c/ usinagem | O22: OK | P22: OK | Q22: Perfil | R22: Serrar | S22: Encaixe | T22: Fur | U22: Acab | V22: Lib | X22: =IF(I22="","AG. FUNDIDO",IF(Q22="AG","AG. USINAGEM","EM USINAGEM")) -> EM USINAGEM | Z22: 25 | AA22: =Tabela1[[#This Row],[Plainar Facear]]+1 -> 26 | AB22: n/a | AC22: =Tabela1[[#This Row],[Serrar2]]+1 -> 27 | AD22: =Tabela1[[#This Row],[Encaixe / Furação]]+1 -> 28
A23: 2203 | B23: 2 | C23: 958023 | D23: 1 | E23: Raizen Ipaussu | F23: BAGACEIRA 78" | G23: 1 | H23: 46185 | I23: 46190 | J23: 46227 | L23: =Tabela1[[#This Row],[Prazo Entrega]]-TODAY() -> -3 | M23: =IF(L23<0,"ATRASADO",IF(L23<=15,"ATENÇÃO","NO PRAZO")) -> ATRASADO | N23: c/ usinagem | O23: OK | P23: OK | Q23: Perfil | R23: Serrar | S23: Encaixe | T23: Fur | U23: Acab | V23: Lib | X23: =IF(I23="","AG. FUNDIDO",IF(Q23="AG","AG. USINAGEM","EM USINAGEM")) -> EM USINAGEM | Z23: 25 | AA23: =Tabela1[[#This Row],[Plainar Facear]]+1 -> 26 | AB23: n/a | AC23: =Tabela1[[#This Row],[Serrar2]]+1 -> 27 | AD23: =Tabela1[[#This Row],[Encaixe / Furação]]+1 -> 28
A24: 2227 | B24: 14 | C24: 1454055 | D24: 1 | E24: MS Internacional | F24: BAGACEIRA 84" | G24: 1 | H24: 46190 | I24: 46184 | J24: 46210 | K24: 46220 | L24: =Tabela1[[#This Row],[Prazo Entrega]]-TODAY() -> -20 | M24: OK | N24: c/ usinagem | O24: OK | P24: OK | Q24: Perfil | R24: Serrar | S24: Encaixe | T24: Fur | U24: Acab | V24: Lib | X24: EXPEDIDO | Z24: 25 | AA24: =Tabela1[[#This Row],[Plainar Facear]]+1 -> 26 | AB24: n/a | AC24: =Tabela1[[#This Row],[Serrar2]]+1 -> 27 | AD24: =Tabela1[[#This Row],[Encaixe / Furação]]+1 -> 28
A25: 2227 | B25: 15 | C25: 1454055 | D25: 2 | E25: MS Internacional | F25: BAGACEIRA 84" | G25: 1 | H25: 46190 | I25: 46184 | J25: 46210 | K25: 46220 | L25: =Tabela1[[#This Row],[Prazo Entrega]]-TODAY() -> -20 | M25: OK | N25: c/ usinagem | O25: OK | P25: OK | Q25: Perfil | R25: Serrar | S25: Encaixe | T25: Fur | U25: Acab | V25: Lib | X25: EXPEDIDO | Z25: 25 | AA25: =Tabela1[[#This Row],[Plainar Facear]]+1 -> 26 | AB25: n/a | AC25: =Tabela1[[#This Row],[Serrar2]]+1 -> 27 | AD25: =Tabela1[[#This Row],[Encaixe / Furação]]+1 -> 28
A26: 2227 | B26: 17 | C26: 1454056 | D26: 2 | E26: MS Internacional | F26: BAGACEIRA 84" | G26: 1 | H26: 46190 | I26: 46184 | J26: 46210 | K26: 46220 | L26: =Tabela1[[#This Row],[Prazo Entrega]]-TODAY() -> -20 | M26: OK | N26: c/ usinagem | O26: OK | P26: OK | Q26: Perfil | R26: Serrar | S26: Encaixe | T26: Fur | U26: Acab | V26: Lib | X26: EXPEDIDO | Z26: 25 | AA26: =Tabela1[[#This Row],[Plainar Facear]]+1 -> 26 | AB26: n/a | AC26: =Tabela1[[#This Row],[Serrar2]]+1 -> 27 | AD26: =Tabela1[[#This Row],[Encaixe / Furação]]+1 -> 28
A27: 2227 | B27: 18 | C27: 1454056 | D27: 1 | E27: MS Internacional | F27: BAGACEIRA 84" | G27: 1 | H27: 46190 | I27: 46184 | J27: 46210 | K27: 46220 | L27: =Tabela1[[#This Row],[Prazo Entrega]]-TODAY() -> -20 | M27: OK | N27: c/ usinagem | O27: OK | P27: OK | Q27: Perfil | R27: Serrar | S27: Encaixe | T27: Fur | U27: Acab | V27: Lib | X27: EXPEDIDO | Z27: 25 | AA27: =Tabela1[[#This Row],[Plainar Facear]]+1 -> 26 | AB27: n/a | AC27: =Tabela1[[#This Row],[Serrar2]]+1 -> 27 | AD27: =Tabela1[[#This Row],[Encaixe / Furação]]+1 -> 28
A28: 2227 | B28: 19 | C28: 1454057 | D28: 1 | E28: MS Internacional | F28: BAGACEIRA 84" | G28: 1 | H28: 46190 | I28: 46184 | J28: 46210 | K28: 46220 | L28: =Tabela1[[#This Row],[Prazo Entrega]]-TODAY() -> -20 | M28: OK | N28: c/ usinagem | O28: OK | P28: OK | Q28: Perfil | R28: Serrar | S28: Encaixe | T28: Fur | U28: Acab | V28: Lib | X28: EXPEDIDO | Z28: 25 | AA28: =Tabela1[[#This Row],[Plainar Facear]]+1 -> 26 | AB28: n/a | AC28: =Tabela1[[#This Row],[Serrar2]]+1 -> 27 | AD28: =Tabela1[[#This Row],[Encaixe / Furação]]+1 -> 28
A29: 2227 | B29: 20 | C29: 1454057 | D29: 2 | E29: MS Internacional | F29: BAGACEIRA 84" | G29: 1 | H29: 46190 | I29: 46184 | J29: 46210 | K29: 46220 | L29: =Tabela1[[#This Row],[Prazo Entrega]]-TODAY() -> -20 | M29: OK | N29: c/ usinagem | O29: OK | P29: OK | Q29: Perfil | R29: Serrar | S29: Encaixe | T29: Fur | U29: Acab | V29: Lib | X29: EXPEDIDO | Z29: 25 | AA29: =Tabela1[[#This Row],[Plainar Facear]]+1 -> 26 | AB29: n/a | AC29: =Tabela1[[#This Row],[Serrar2]]+1 -> 27 | AD29: =Tabela1[[#This Row],[Encaixe / Furação]]+1 -> 28
A30: 2203 | B30: 3 | C30: 958024 | D30: 1 | E30: Raizen Ipaussu | F30: BAGACEIRA 78" | G30: 1 | H30: 46185 | I30: 46192 | J30: 46227 | L30: =Tabela1[[#This Row],[Prazo Entrega]]-TODAY() -> -3 | M30: =IF(L30<0,"ATRASADO",IF(L30<=15,"ATENÇÃO","NO PRAZO")) -> ATRASADO | N30: c/ usinagem | O30: OK | P30: OK | Q30: Perfil | R30: Serrar | S30: Encaixe | T30: Fur | U30: Acab | V30: Lib | X30: =IF(I30="","AG. FUNDIDO",IF(Q30="AG","AG. USINAGEM","EM USINAGEM")) -> EM USINAGEM | Z30: 27 | AA30: =Tabela1[[#This Row],[Plainar Facear]]+1 -> 28 | AB30: n/a | AC30: =Tabela1[[#This Row],[Serrar2]]+1 -> 29 | AD30: =Tabela1[[#This Row],[Encaixe / Furação]]+1 -> 30
A31: 2202 | B31: 1 | C31: 1256014 | D31: 1 | E31: Raizen Diamante | F31: BAGACEIRA 78" | G31: 1 | H31: 46185 | I31: 46175 | J31: 46213 | K31: 46199 | L31: =Tabela1[[#This Row],[Prazo Entrega]]-TODAY() -> -17 | M31: =IF(L31<0,"ATRASADO",IF(L31<=15,"ATENÇÃO","NO PRAZO")) -> ATRASADO | N31: c/ usinagem | O31: OK | P31: OK | Q31: Perfil | R31: Serrar | S31: Encaixe | T31: Fur | U31: Acab | V31: Insp. | X31: AG. COLETAR | Z31: 27 | AA31: =Tabela1[[#This Row],[Plainar Facear]]+1 -> 28 | AB31: n/a | AC31: =Tabela1[[#This Row],[Serrar2]]+1 -> 29 | AD31: =Tabela1[[#This Row],[Encaixe / Furação]]+1 -> 30
A32: 2202 | B32: 2 | C32: 1256015 | D32: 1 | E32: Raizen Diamante | F32: BAGACEIRA 78" | G32: 1 | H32: 46185 | I32: 46175 | J32: 46220 | K32: 46220 | L32: =Tabela1[[#This Row],[Prazo Entrega]]-TODAY() -> -10 | M32: =IF(L32<0,"ATRASADO",IF(L32<=15,"ATENÇÃO","NO PRAZO")) -> ATRASADO | N32: c/ usinagem | O32: OK | P32: OK | Q32: Perfil | R32: Serrar | S32: Encaixe | T32: Fur | U32: Acab | V32: Insp. | X32: AG. COLETAR | Z32: 27 | AA32: =Tabela1[[#This Row],[Plainar Facear]]+1 -> 28 | AB32: n/a | AC32: =Tabela1[[#This Row],[Serrar2]]+1 -> 29 | AD32: =Tabela1[[#This Row],[Encaixe / Furação]]+1 -> 30
A33: 2202 | B33: 3 | C33: 1256016 | D33: 1 | E33: Raizen Diamante | F33: BAGACEIRA 78" | G33: 1 | H33: 46185 | I33: 46175 | J33: 46227 | K33: 46227 | L33: =Tabela1[[#This Row],[Prazo Entrega]]-TODAY() -> -3 | M33: =IF(L33<0,"ATRASADO",IF(L33<=15,"ATENÇÃO","NO PRAZO")) -> ATRASADO | N33: c/ usinagem | O33: OK | P33: OK | Q33: Perfil | R33: Serrar | S33: Encaixe | T33: Fur | U33: Acab | V33: Insp. | X33: AG. COLETAR | Z33: 27 | AA33: =Tabela1[[#This Row],[Plainar Facear]]+1 -> 28 | AB33: n/a | AC33: =Tabela1[[#This Row],[Serrar2]]+1 -> 29 | AD33: =Tabela1[[#This Row],[Encaixe / Furação]]+1 -> 30
A34: 2202 | B34: 4 | C34: 1256017 | D34: 1 | E34: Raizen Diamante | F34: BAGACEIRA 78" | G34: 1 | H34: 46185 | I34: 46175 | J34: 46220 | K34: 46220 | L34: =Tabela1[[#This Row],[Prazo Entrega]]-TODAY() -> -10 | M34: =IF(L34<0,"ATRASADO",IF(L34<=15,"ATENÇÃO","NO PRAZO")) -> ATRASADO | N34: c/ usinagem | O34: OK | P34: OK | Q34: Perfil | R34: Serrar | S34: Encaixe | T34: Fur | U34: Acab | V34: Insp. | X34: EXPEDIDO | Z34: 27 | AA34: =Tabela1[[#This Row],[Plainar Facear]]+1 -> 28 | AB34: n/a | AC34: =Tabela1[[#This Row],[Serrar2]]+1 -> 29 | AD34: =Tabela1[[#This Row],[Encaixe / Furação]]+1 -> 30
A35: 2202 | B35: 5 | C35: 1256018 | D35: 1 | E35: Raizen Diamante | F35: BAGACEIRA 78" | G35: 1 | H35: 46185 | I35: 46175 | J35: 46227 | K35: 46227 | L35: =Tabela1[[#This Row],[Prazo Entrega]]-TODAY() -> -3 | M35: =IF(L35<0,"ATRASADO",IF(L35<=15,"ATENÇÃO","NO PRAZO")) -> ATRASADO | N35: c/ usinagem | O35: OK | P35: OK | Q35: Perfil | R35: Serrar | S35: Encaixe | T35: Fur | U35: Acab | V35: Insp. | X35: AG. COLETAR | Z35: 27 | AA35: =Tabela1[[#This Row],[Plainar Facear]]+1 -> 28 | AB35: n/a | AC35: =Tabela1[[#This Row],[Serrar2]]+1 -> 29 | AD35: =Tabela1[[#This Row],[Encaixe / Furação]]+1 -> 30
A36: 2201 | B36: 9 | C36: 1148038 | D36: 1 | E36: Raizen Costa Pinto | F36: BAGACEIRA 78" | G36: 1 | H36: 46185 | I36: 46189 | J36: 46220 | K36: 46220 | L36: =Tabela1[[#This Row],[Prazo Entrega]]-TODAY() -> -10 | M36: =IF(L36<0,"ATRASADO",IF(L36<=15,"ATENÇÃO","NO PRAZO")) -> ATRASADO | N36: c/ usinagem | O36: OK | P36: OK | Q36: Perfil | R36: Serrar | S36: Encaixe | T36: Fur | U36: Acab | V36: Insp. | X36: EXPEDIDO | Z36: 27 | AA36: =Tabela1[[#This Row],[Plainar Facear]]+1 -> 28 | AB36: n/a | AC36: =Tabela1[[#This Row],[Serrar2]]+1 -> 29 | AD36: =Tabela1[[#This Row],[Encaixe / Furação]]+1 -> 30
A37: 2201 | B37: 10 | C37: 1148039 | D37: 1 | E37: Raizen Costa Pinto | F37: BAGACEIRA 84" | G37: 1 | H37: 46185 | I37: 46192 | J37: 46227 | L37: =Tabela1[[#This Row],[Prazo Entrega]]-TODAY() -> -3 | M37: =IF(L37<0,"ATRASADO",IF(L37<=15,"ATENÇÃO","NO PRAZO")) -> ATRASADO | N37: c/ usinagem | O37: OK | P37: OK | Q37: Perfil | R37: Serrar | S37: Encaixe | T37: Fur | U37: Acab | V37: Insp. | X37: =IF(I37="","AG. FUNDIDO",IF(Q37="AG","AG. USINAGEM","EM USINAGEM")) -> EM USINAGEM | Y37: RNC 13892 - BAGACEIRA CÓD. 1148039 - REFUGADA POR FALTA DE MATERIAL. | Z37: 27 | AA37: =Tabela1[[#This Row],[Plainar Facear]]+1 -> 28 | AB37: n/a | AC37: =Tabela1[[#This Row],[Serrar2]]+1 -> 29 | AD37: =Tabela1[[#This Row],[Encaixe / Furação]]+1 -> 30
A38: 2205 | B38: 1 | C38: 1483008 | D38: 1 | E38: Raizen Paraiso | F38: BAGACEIRA 78" | G38: 1 | H38: 46192 | I38: 46175 | J38: 46234 | L38: =Tabela1[[#This Row],[Prazo Entrega]]-TODAY() -> 4 | M38: =IF(L38<0,"ATRASADO",IF(L38<=15,"ATENÇÃO","NO PRAZO")) -> ATENÇÃO | N38: c/ usinagem | O38: OK | P38: OK | Q38: Perfil | R38: Serrar | S38: Encaixe | T38: Fur | U38: Acab | V38: Insp. | X38: =IF(I38="","AG. FUNDIDO",IF(Q38="AG","AG. USINAGEM","EM USINAGEM")) -> EM USINAGEM | Z38: 27 | AA38: =Tabela1[[#This Row],[Plainar Facear]]+1 -> 28 | AB38: n/a | AC38: =Tabela1[[#This Row],[Serrar2]]+1 -> 29 | AD38: =Tabela1[[#This Row],[Encaixe / Furação]]+1 -> 30
A39: 2204 | B39: 1 | C39: 1334017 | D39: 1 | E39: Raizen Lagoa da Prata | F39: BAGACEIRA 78" | G39: 1 | H39: 46192 | I39: 46233 | J39: 46234 | L39: =Tabela1[[#This Row],[Prazo Entrega]]-TODAY() -> 4 | M39: =IF(L39<0,"ATRASADO",IF(L39<=15,"ATENÇÃO","NO PRAZO")) -> ATENÇÃO | N39: c/ usinagem | O39: OK | P39: OK | Q39: Perfil | R39: Serrar | S39: Encaixe | T39: Fur | U39: Acab | V39: Insp. | X39: =IF(I39="","AG. FUNDIDO",IF(Q39="AG","AG. USINAGEM","EM USINAGEM")) -> EM USINAGEM | Z39: 27 | AA39: =Tabela1[[#This Row],[Plainar Facear]]+1 -> 28 | AB39: n/a | AC39: =Tabela1[[#This Row],[Serrar2]]+1 -> 29 | AD39: =Tabela1[[#This Row],[Encaixe / Furação]]+1 -> 30
A40: 2204 | B40: 2 | C40: 1334018 | D40: 1 | E40: Raizen Lagoa da Prata | F40: BAGACEIRA 78" | G40: 1 | H40: 46192 | I40: 46217 | J40: 46234 | L40: =Tabela1[[#This Row],[Prazo Entrega]]-TODAY() -> 4 | M40: =IF(L40<0,"ATRASADO",IF(L40<=15,"ATENÇÃO","NO PRAZO")) -> ATENÇÃO | N40: c/ usinagem | O40: OK | P40: OK | Q40: Perfil | R40: Serrar | S40: Encaixe | T40: Fur | U40: Acab | V40: Insp. | X40: =IF(I40="","AG. FUNDIDO",IF(Q40="AG","AG. USINAGEM","EM USINAGEM")) -> EM USINAGEM | Z40: 28 | AA40: =Tabela1[[#This Row],[Plainar Facear]]+1 -> 29 | AB40: n/a | AC40: =Tabela1[[#This Row],[Serrar2]]+1 -> 30 | AD40: =Tabela1[[#This Row],[Encaixe / Furação]]+1 -> 31
...

Sheet PENTES
A1: PV | B1: Item | C1: OS/ Peça | D1: Seq. | E1: Cliente | F1: Descrição | G1: Qtde. | H1: Prazo Fundido | I1: Pz Fundido Real | J1: Prazo Entrega | K1: Pz Entrega Real | L1: Desenho Previsão | M1: Des. | N1: Dias Falta2 | O1: Indicador | P1: CONDIÇÃO | Q1: OP1 | R1: OP2 | S1: OP3 | T1: OP4 | U1: OP5 | V1: Status Usinagem | W1: Observação
A2: 2226 | B2: 7 | C2: 1495052 | D2: 1 | E2: Aura Brazil | F2: PENTE CURVO - USINADO LISO | G2: 1 | H2: 46185 | I2: 46188 | J2: 46211 | L2: OK | M2: OK | N2: OK | O2: =IF(N2<0,"ATRASADO",IF(N2<=15,"ATENÇÃO","NO PRAZO")) -> NO PRAZO | P2: c/ usinagem | Q2: Enviar Terc. | R2: Retornar | S2: Acab. | T2: Insp | V2: AG. COLETA
A3: 2226 | B3: 8 | C3: 1495052 | D3: 2 | E3: Aura Brazil | F3: PENTE CURVO - USINADO LISO | G3: 1 | H3: 46185 | I3: 46188 | J3: 46211 | L3: OK | M3: OK | N3: OK | O3: =IF(N3<0,"ATRASADO",IF(N3<=15,"ATENÇÃO","NO PRAZO")) -> NO PRAZO | P3: c/ usinagem | Q3: Enviar Terc. | R3: Retornar | S3: Acab. | T3: Insp | V3: AG. COLETA
A4: 2226 | B4: 9 | C4: 1495052 | D4: 3 | E4: Aura Brazil | F4: PENTE CURVO - USINADO LISO | G4: 1 | H4: 46185 | I4: 46188 | J4: 46211 | L4: OK | M4: OK | N4: OK | O4: =IF(N4<0,"ATRASADO",IF(N4<=15,"ATENÇÃO","NO PRAZO")) -> NO PRAZO | P4: c/ usinagem | Q4: Enviar Terc. | R4: Retornar | S4: Acab. | T4: Insp | V4: AG. COLETA
A5: 2226 | B5: 10 | C5: 1495052 | D5: 4 | E5: Aura Brazil | F5: PENTE CURVO - USINADO LISO | G5: 1 | H5: 46185 | I5: 46188 | J5: 46211 | L5: OK | M5: OK | N5: OK | O5: =IF(N5<0,"ATRASADO",IF(N5<=15,"ATENÇÃO","NO PRAZO")) -> NO PRAZO | P5: c/ usinagem | Q5: Enviar Terc. | R5: Retornar | S5: Acab. | T5: Insp | V5: AG. COLETA
A6: 2226 | B6: 11 | C6: 1495052 | D6: 5 | E6: Aura Brazil | F6: PENTE CURVO - USINADO LISO | G6: 1 | H6: 46185 | I6: 46188 | J6: 46211 | L6: OK | M6: OK | N6: OK | O6: =IF(N6<0,"ATRASADO",IF(N6<=15,"ATENÇÃO","NO PRAZO")) -> NO PRAZO | P6: c/ usinagem | Q6: Enviar Terc. | R6: Retornar | S6: Acab. | T6: Insp | V6: AG. COLETA
A7: 2226 | B7: 12 | C7: 1495052 | D7: 6 | E7: Aura Brazil | F7: PENTE CURVO - USINADO LISO | G7: 1 | H7: 46185 | I7: 46188 | J7: 46211 | L7: OK | M7: OK | N7: OK | O7: =IF(N7<0,"ATRASADO",IF(N7<=15,"ATENÇÃO","NO PRAZO")) -> NO PRAZO | P7: c/ usinagem | Q7: Enviar Terc. | R7: Retornar | S7: Acab. | T7: Insp | V7: AG. COLETA
A8: 2226 | B8: 13 | C8: 1495052 | D8: 7 | E8: Aura Brazil | F8: PENTE CURVO - USINADO LISO | G8: 1 | H8: 46185 | I8: 46188 | J8: 46211 | L8: OK | M8: OK | N8: OK | O8: =IF(N8<0,"ATRASADO",IF(N8<=15,"ATENÇÃO","NO PRAZO")) -> NO PRAZO | P8: c/ usinagem | Q8: Enviar Terc. | R8: Retornar | S8: Acab. | T8: Insp | V8: AG. COLETA
A9: 2226 | B9: 14 | C9: 1495052 | D9: 8 | E9: Aura Brazil | F9: PENTE CURVO - USINADO LISO | G9: 1 | H9: 46185 | I9: 46188 | J9: 46211 | L9: OK | M9: OK | N9: OK | O9: =IF(N9<0,"ATRASADO",IF(N9<=15,"ATENÇÃO","NO PRAZO")) -> NO PRAZO | P9: c/ usinagem | Q9: Enviar Terc. | R9: Retornar | S9: Acab. | T9: Insp | V9: AG. COLETA
A10: 2226 | B10: 15 | C10: 1495052 | D10: 9 | E10: Aura Brazil | F10: PENTE CURVO - USINADO LISO | G10: 1 | H10: 46185 | I10: 46188 | J10: 46211 | L10: OK | M10: OK | N10: OK | O10: =IF(N10<0,"ATRASADO",IF(N10<=15,"ATENÇÃO","NO PRAZO")) -> NO PRAZO | P10: c/ usinagem | Q10: Enviar Terc. | R10: Retornar | S10: Acab. | T10: Insp | V10: AG. COLETA
A11: 2226 | B11: 17 | C11: 1495054 | D11: 1 | E11: Aura Brazil | F11: PENTE CURVO - USINADO LISO | G11: 1 | H11: 46185 | I11: 46188 | J11: 46211 | L11: OK | M11: OK | N11: OK | O11: =IF(N11<0,"ATRASADO",IF(N11<=15,"ATENÇÃO","NO PRAZO")) -> NO PRAZO | P11: c/ usinagem | Q11: Enviar Terc. | R11: Retornar | S11: Acab. | T11: Insp | V11: AG. COLETA | W11: RNC 13867 - FUNDIU PENTE 66"
A12: 2226 | B12: 18 | C12: 1495054 | D12: 2 | E12: Aura Brazil | F12: PENTE CURVO - USINADO LISO | G12: 1 | H12: 46185 | I12: 46188 | J12: 46211 | L12: OK | M12: OK | N12: OK | O12: =IF(N12<0,"ATRASADO",IF(N12<=15,"ATENÇÃO","NO PRAZO")) -> NO PRAZO | P12: c/ usinagem | Q12: Enviar Terc. | R12: Retornar | S12: Acab. | T12: Insp | V12: AG. COLETA | W12: RNC 13868 - FUNDIU PENTE 66"
A13: 2226 | B13: 19 | C13: 1495054 | D13: 3 | E13: Aura Brazil | F13: PENTE CURVO - USINADO LISO | G13: 1 | H13: 46185 | I13: 46188 | J13: 46211 | L13: OK | M13: OK | N13: OK | O13: =IF(N13<0,"ATRASADO",IF(N13<=15,"ATENÇÃO","NO PRAZO")) -> NO PRAZO | P13: c/ usinagem | Q13: Enviar Terc. | R13: Retornar | S13: Acab. | T13: Insp | V13: AG. COLETA | W13: RNC 13869 - FUNDIU PENTE 66"
A14: 2227 | B14: 1 | C14: 1454053 | D14: 1 | E14: MS Internacional | F14: PENTE INFERIOR CONVENCIONAL 84" | G14: 1 | H14: 46185 | I14: 46190 | J14: 46211 | K14: 46211 | L14: OK | M14: OK | N14: OK | O14: =IF(N14<0,"ATRASADO",IF(N14<=15,"ATENÇÃO","NO PRAZO")) -> NO PRAZO | P14: c/ usinagem | Q14: Enviar Terc. | R14: Retornar | S14: Acab. | T14: Insp | V14: EXPEDIDO
A15: 2227 | B15: 2 | C15: 1454053 | D15: 2 | E15: MS Internacional | F15: PENTE INFERIOR CONVENCIONAL 84" | G15: 1 | H15: 46185 | I15: 46190 | J15: 46211 | K15: 46211 | L15: OK | M15: OK | N15: OK | O15: =IF(N15<0,"ATRASADO",IF(N15<=15,"ATENÇÃO","NO PRAZO")) -> NO PRAZO | P15: c/ usinagem | Q15: Enviar Terc. | R15: Retornar | S15: Acab. | T15: Insp | V15: EXPEDIDO
A16: 2227 | B16: 3 | C16: 1454053 | D16: 3 | E16: MS Internacional | F16: PENTE INFERIOR CONVENCIONAL 84" | G16: 1 | H16: 46185 | I16: 46190 | J16: 46211 | K16: 46211 | L16: OK | M16: OK | N16: OK | O16: =IF(N16<0,"ATRASADO",IF(N16<=15,"ATENÇÃO","NO PRAZO")) -> NO PRAZO | P16: c/ usinagem | Q16: Enviar Terc. | R16: Retornar | S16: Acab. | T16: Insp | V16: EXPEDIDO
A17: 2227 | B17: 4 | C17: 1454053 | D17: 4 | E17: MS Internacional | F17: PENTE INFERIOR CONVENCIONAL 84" | G17: 1 | H17: 46185 | I17: 46190 | J17: 46211 | K17: 46211 | L17: OK | M17: OK | N17: OK | O17: =IF(N17<0,"ATRASADO",IF(N17<=15,"ATENÇÃO","NO PRAZO")) -> NO PRAZO | P17: c/ usinagem | Q17: Enviar Terc. | R17: Retornar | S17: Acab. | T17: Insp | V17: EXPEDIDO
A18: 2227 | B18: 5 | C18: 1454054 | D18: 1 | E18: MS Internacional | F18: PENTE SUPERIOR CONVENCIONAL 84" | G18: 1 | H18: 46185 | I18: 46188 | J18: 46211 | K18: 46211 | L18: OK | M18: OK | N18: OK | O18: =IF(N18<0,"ATRASADO",IF(N18<=15,"ATENÇÃO","NO PRAZO")) -> NO PRAZO | P18: c/ usinagem | Q18: Enviar Terc. | R18: Retornar | S18: Acab. | T18: Insp | V18: EXPEDIDO
A19: 2227 | B19: 6 | C19: 1454054 | D19: 2 | E19: MS Internacional | F19: PENTE SUPERIOR CONVENCIONAL 84" | G19: 1 | H19: 46185 | I19: 46188 | J19: 46211 | K19: 46211 | L19: OK | M19: OK | N19: OK | O19: =IF(N19<0,"ATRASADO",IF(N19<=15,"ATENÇÃO","NO PRAZO")) -> NO PRAZO | P19: c/ usinagem | Q19: Enviar Terc. | R19: Retornar | S19: Acab. | T19: Insp | V19: EXPEDIDO
A20: 2227 | B20: 7 | C20: 1454054 | D20: 3 | E20: MS Internacional | F20: PENTE SUPERIOR CONVENCIONAL 84" | G20: 1 | H20: 46185 | I20: 46188 | J20: 46211 | K20: 46211 | L20: OK | M20: OK | N20: OK | O20: =IF(N20<0,"ATRASADO",IF(N20<=15,"ATENÇÃO","NO PRAZO")) -> NO PRAZO | P20: c/ usinagem | Q20: Enviar Terc. | R20: Retornar | S20: Acab. | T20: Insp | V20: EXPEDIDO
A21: 2227 | B21: 8 | C21: 1454053 | D21: 5 | E21: MS Internacional | F21: PENTE INFERIOR CONVENCIONAL 84" | G21: 1 | H21: 46185 | I21: 46190 | J21: 46211 | K21: 46211 | L21: OK | M21: OK | N21: OK | O21: =IF(N21<0,"ATRASADO",IF(N21<=15,"ATENÇÃO","NO PRAZO")) -> NO PRAZO | P21: c/ usinagem | Q21: Enviar Terc. | R21: Retornar | S21: Acab. | T21: Insp | V21: EXPEDIDO
A22: 2227 | B22: 9 | C22: 1454053 | D22: 6 | E22: MS Internacional | F22: PENTE INFERIOR CONVENCIONAL 84" | G22: 1 | H22: 46185 | I22: 46190 | J22: 46211 | K22: 46211 | L22: OK | M22: OK | N22: OK | O22: =IF(N22<0,"ATRASADO",IF(N22<=15,"ATENÇÃO","NO PRAZO")) -> NO PRAZO | P22: c/ usinagem | Q22: Enviar Terc. | R22: Retornar | S22: Acab. | T22: Insp | V22: EXPEDIDO
A23: 2227 | B23: 10 | C23: 1454053 | D23: 7 | E23: MS Internacional | F23: PENTE INFERIOR CONVENCIONAL 84" | G23: 1 | H23: 46185 | I23: 46190 | J23: 46211 | K23: 46211 | L23: OK | M23: OK | N23: OK | O23: =IF(N23<0,"ATRASADO",IF(N23<=15,"ATENÇÃO","NO PRAZO")) -> NO PRAZO | P23: c/ usinagem | Q23: Enviar Terc. | R23: Retornar | S23: Acab. | T23: Insp | V23: EXPEDIDO
A24: 2227 | B24: 11 | C24: 1454053 | D24: 8 | E24: MS Internacional | F24: PENTE INFERIOR CONVENCIONAL 84" | G24: 1 | H24: 46185 | I24: 46190 | J24: 46211 | K24: 46211 | L24: OK | M24: OK | N24: OK | O24: =IF(N24<0,"ATRASADO",IF(N24<=15,"ATENÇÃO","NO PRAZO")) -> NO PRAZO | P24: c/ usinagem | Q24: Enviar Terc. | R24: Retornar | S24: Acab. | T24: Insp | V24: EXPEDIDO
A25: 2227 | B25: 12 | C25: 1454054 | D25: 4 | E25: MS Internacional | F25: PENTE SUPERIOR CONVENCIONAL 84" | G25: 1 | H25: 46185 | I25: 46188 | J25: 46211 | K25: 46211 | L25: OK | M25: OK | N25: OK | O25: =IF(N25<0,"ATRASADO",IF(N25<=15,"ATENÇÃO","NO PRAZO")) -> NO PRAZO | P25: c/ usinagem | Q25: Enviar Terc. | R25: Retornar | S25: Acab. | T25: Insp | V25: EXPEDIDO
A26: 2227 | B26: 13 | C26: 1454054 | D26: 5 | E26: MS Internacional | F26: PENTE SUPERIOR CONVENCIONAL 84" | G26: 1 | H26: 46185 | I26: 46188 | J26: 46211 | K26: 46211 | L26: OK | M26: OK | N26: OK | O26: =IF(N26<0,"ATRASADO",IF(N26<=15,"ATENÇÃO","NO PRAZO")) -> NO PRAZO | P26: c/ usinagem | Q26: Enviar Terc. | R26: Retornar | S26: Acab. | T26: Insp | V26: EXPEDIDO
A27: 2227 | B27: 21 | C27: CHAPA | D27: - | E27: MS Internacional | F27: PENTE SUPERIOR EM CHAPA RETO 82" | G27: 1 | H27: 46183 | I27: 46183 | J27: 46211 | K27: 46211 | L27: OK | M27: OK | N27: OK | O27: =IF(N27<0,"ATRASADO",IF(N27<=15,"ATENÇÃO","NO PRAZO")) -> NO PRAZO | P27: c/ usinagem | Q27: Enviar Terc. | R27: Retornar | S27: Acab. | T27: Insp | V27: EXPEDIDO
A28: 2227 | B28: 22 | C28: CHAPA | D28: - | E28: MS Internacional | F28: PENTE SUPERIOR EM CHAPA RETO 82" | G28: 1 | H28: 46183 | I28: 46183 | J28: 46211 | K28: 46211 | L28: OK | M28: OK | N28: OK | O28: =IF(N28<0,"ATRASADO",IF(N28<=15,"ATENÇÃO","NO PRAZO")) -> NO PRAZO | P28: c/ usinagem | Q28: Enviar Terc. | R28: Retornar | S28: Acab. | T28: Insp | V28: EXPEDIDO
A29: 2227 | B29: 23 | C29: CHAPA | D29: - | E29: MS Internacional | F29: PENTE SUPERIOR EM CHAPA RETO 82" | G29: 1 | H29: 46183 | I29: 46183 | J29: 46211 | K29: 46211 | L29: OK | M29: OK | N29: OK | O29: =IF(N29<0,"ATRASADO",IF(N29<=15,"ATENÇÃO","NO PRAZO")) -> NO PRAZO | P29: c/ usinagem | Q29: Enviar Terc. | R29: Retornar | S29: Acab. | T29: Insp | V29: EXPEDIDO
A30: 2227 | B30: 24 | C30: CHAPA | D30: - | E30: MS Internacional | F30: PENTE SUPERIOR EM CHAPA RETO 82" | G30: 1 | H30: 46183 | I30: 46183 | J30: 46211 | K30: 46211 | L30: OK | M30: OK | N30: OK | O30: =IF(N30<0,"ATRASADO",IF(N30<=15,"ATENÇÃO","NO PRAZO")) -> NO PRAZO | P30: c/ usinagem | Q30: Enviar Terc. | R30: Retornar | S30: Acab. | T30: Insp | V30: EXPEDIDO
A31: 2227 | B31: 25 | C31: CHAPA | D31: - | E31: MS Internacional | F31: PENTE SUPERIOR EM CHAPA RETO 82" | G31: 1 | H31: 46183 | I31: 46183 | J31: 46211 | K31: 46211 | L31: OK | M31: OK | N31: OK | O31: =IF(N31<0,"ATRASADO",IF(N31<=15,"ATENÇÃO","NO PRAZO")) -> NO PRAZO | P31: c/ usinagem | Q31: Enviar Terc. | R31: Retornar | S31: Acab. | T31: Insp | V31: EXPEDIDO
A32: 2227 | B32: 26 | C32: CHAPA | D32: - | E32: MS Internacional | F32: PENTE SUPERIOR EM CHAPA RETO 82" | G32: 1 | H32: 46183 | I32: 46183 | J32: 46211 | K32: 46211 | L32: OK | M32: OK | N32: OK | O32: =IF(N32<0,"ATRASADO",IF(N32<=15,"ATENÇÃO","NO PRAZO")) -> NO PRAZO | P32: c/ usinagem | Q32: Enviar Terc. | R32: Retornar | S32: Acab. | T32: Insp | V32: EXPEDIDO
A33: 1951 | B33: 9 | C33: 1202015 | D33: - | E33: Cofco Potirendaba | F33: PENTE SUPERIOR CURVO 78" | G33: 1 | H33: 46190 | I33: 46190 | J33: 46233 | L33: OK | M33: OK | N33: =Tabela3[[#This Row],[Prazo Entrega]]-TODAY() -> 3 | O33: =IF(N33<0,"ATRASADO",IF(N33<=15,"ATENÇÃO","NO PRAZO")) -> ATENÇÃO | P33: c/ usinagem | Q33: Enviar Terc. | R33: Retornar | S33: Solda Dura | T33: Acab. | U33: Insp | V33: EM USINAGEM
A34: 1951 | B34: 10 | C34: 1202015 | D34: - | E34: Cofco Potirendaba | F34: PENTE SUPERIOR CURVO 78" | G34: 1 | H34: 46190 | I34: 46190 | J34: 46233 | L34: OK | M34: OK | N34: =Tabela3[[#This Row],[Prazo Entrega]]-TODAY() -> 3 | O34: =IF(N34<0,"ATRASADO",IF(N34<=15,"ATENÇÃO","NO PRAZO")) -> ATENÇÃO | P34: c/ usinagem | Q34: Enviar Terc. | R34: Retornar | S34: Solda Dura | T34: Acab. | U34: Insp | V34: EM USINAGEM
A35: 1951 | B35: 11 | C35: 1202015 | D35: - | E35: Cofco Potirendaba | F35: PENTE SUPERIOR CURVO 78" | G35: 1 | H35: 46190 | I35: 46190 | J35: 46233 | L35: OK | M35: OK | N35: =Tabela3[[#This Row],[Prazo Entrega]]-TODAY() -> 3 | O35: =IF(N35<0,"ATRASADO",IF(N35<=15,"ATENÇÃO","NO PRAZO")) -> ATENÇÃO | P35: c/ usinagem | Q35: Enviar Terc. | R35: Retornar | S35: Solda Dura | T35: Acab. | U35: Insp | V35: EM USINAGEM
A36: 1951 | B36: 12 | C36: 1202015 | D36: - | E36: Cofco Potirendaba | F36: PENTE SUPERIOR CURVO 78" | G36: 1 | H36: 46190 | I36: 46190 | J36: 46233 | L36: OK | M36: OK | N36: =Tabela3[[#This Row],[Prazo Entrega]]-TODAY() -> 3 | O36: =IF(N36<0,"ATRASADO",IF(N36<=15,"ATENÇÃO","NO PRAZO")) -> ATENÇÃO | P36: c/ usinagem | Q36: Enviar Terc. | R36: Retornar | S36: Solda Dura | T36: Acab. | U36: Insp | V36: EM USINAGEM
A37: 1951 | B37: 13 | C37: 1202015 | D37: - | E37: Cofco Potirendaba | F37: PENTE SUPERIOR CURVO 78" | G37: 1 | H37: 46190 | I37: 46190 | J37: 46233 | L37: OK | M37: OK | N37: =Tabela3[[#This Row],[Prazo Entrega]]-TODAY() -> 3 | O37: =IF(N37<0,"ATRASADO",IF(N37<=15,"ATENÇÃO","NO PRAZO")) -> ATENÇÃO | P37: c/ usinagem | Q37: Enviar Terc. | R37: Retornar | S37: Solda Dura | T37: Acab. | U37: Insp | V37: EM USINAGEM
A38: 1031 | B38: 3 | C38: 464066 | D38: 22 | E38: Água Bonita | F38: PENTE SUPERIOR CONVENCIONAL 84" | G38: 1 | H38: 46226 | I38: 46227 | J38: 46266 | L38: OK | M38: OK | N38: =Tabela3[[#This Row],[Prazo Entrega]]-TODAY() -> 36 | O38: =IF(N38<0,"ATRASADO",IF(N38<=15,"ATENÇÃO","NO PRAZO")) -> NO PRAZO | P38: c/ usinagem | Q38: Enviar Terc. | R38: Retornar | S38: Acab. | T38: Insp | V38: EM USINAGEM
A39: 1031 | B39: 4 | C39: 464066 | D39: 23 | E39: Água Bonita | F39: PENTE SUPERIOR CONVENCIONAL 84" | G39: 1 | H39: 46226 | I39: 46227 | J39: 46266 | L39: OK | M39: OK | N39: =Tabela3[[#This Row],[Prazo Entrega]]-TODAY() -> 36 | O39: =IF(N39<0,"ATRASADO",IF(N39<=15,"ATENÇÃO","NO PRAZO")) -> NO PRAZO | P39: c/ usinagem | Q39: Enviar Terc. | R39: Retornar | S39: Acab. | T39: Insp | V39: EM USINAGEM
A40: 1031 | B40: 5 | C40: 464066 | D40: 24 | E40: Água Bonita | F40: PENTE SUPERIOR CONVENCIONAL 84" | G40: 1 | H40: 46226 | I40: 46227 | J40: 46266 | L40: OK | M40: OK | N40: =Tabela3[[#This Row],[Prazo Entrega]]-TODAY() -> 36 | O40: =IF(N40<0,"ATRASADO",IF(N40<=15,"ATENÇÃO","NO PRAZO")) -> NO PRAZO | P40: c/ usinagem | Q40: Enviar Terc. | R40: Retornar | S40: Acab. | T40: Insp | V40: EM USINAGEM
...

Sheet RODETES NOVOS
A1: PV | B1: Item | C1: OS/ Peça | D1: Seq. | E1: Cliente | F1: Descrição | G1: Qtd. | H1: Data Prev. Fundido | I1: Data Real Fundido | J1: Data Prev. Entrega | K1: Data Real Entrega | L1: Falta Dias | M1: Indicador | N1: Condição | O1: Desenho Previsão | P1: Des. | Q1: OP1 | R1: OP2 | S1: OP3 | T1: OP4 | U1: OP5 | V1: OP6 | W1: OP7 | X1: Status Usinagem | Y1: Observação
A2: 2233 | B2: 1 | C2: 250039 | D2: 1 | E2: Coprodria | F2: RODETE MDA Z15 Ø1320MM 78" | G2: 1 | H2: 46209 | J2: 46269 | L2: =Tabela13[[#This Row],[Data Prev. Entrega]]-TODAY() -> 39 | M2: =IF(L2<0,"ATRASADO",IF(L2<=15,"ATENÇÃO","NO PRAZO")) -> NO PRAZO | N2: c/ usinagem | O2: OK | P2: OK | Q2: Desb | R2: Envia T.T. | S2: Retorno T.T. | T2: Torno | U2: F. Dente | V2: Acab. | W2: Insp. | X2: =IF(I2="","AG. FUNDIDO",IF(W2="OK","LIBERADA","EM USINAGEM")) -> AG. FUNDIDO
A3: 2233 | B3: 2 | C3: 250040 | D3: 1 | E3: Coprodria | F3: RODETE MDA Z15 Ø1280MM 78" | G3: 1 | H3: 46209 | J3: 46269 | L3: =Tabela13[[#This Row],[Data Prev. Entrega]]-TODAY() -> 39 | M3: =IF(L3<0,"ATRASADO",IF(L3<=15,"ATENÇÃO","NO PRAZO")) -> NO PRAZO | N3: c/ usinagem | O3: OK | P3: OK | Q3: Desb | R3: Envia T.T. | S3: Retorno T.T. | T3: Torno | U3: F. Dente | V3: Acab. | W3: Insp. | X3: =IF(I3="","AG. FUNDIDO",IF(W3="OK","LIBERADA","EM USINAGEM")) -> AG. FUNDIDO
A4: 2284 | B4: 1 | C4: 212076 | D4: 1 | E4: Simisa | F4: RODETE MDA Z15 (BRUTO) | G4: 1 | H4: 46239 | J4: 46239 | L4: =Tabela13[[#This Row],[Data Prev. Entrega]]-TODAY() -> 9 | M4: =IF(L4<0,"ATRASADO",IF(L4<=15,"ATENÇÃO","NO PRAZO")) -> ATENÇÃO | N4: Bruto | O4: - | P4: - | Q4: - | R4: - | S4: - | T4: - | U4: - | V4: - | W4: - | X4: =IF(I4="","AG. FUNDIDO",IF(W4="OK","LIBERADA","EM USINAGEM")) -> AG. FUNDIDO
A5: 2284 | B5: 2 | C5: 212076 | D5: 2 | E5: Simisa | F5: RODETE MDA Z15 (BRUTO) | G5: 1 | H5: 46239 | J5: 46239 | L5: =Tabela13[[#This Row],[Data Prev. Entrega]]-TODAY() -> 9 | M5: =IF(L5<0,"ATRASADO",IF(L5<=15,"ATENÇÃO","NO PRAZO")) -> ATENÇÃO | N5: Bruto | O5: - | P5: - | Q5: - | R5: - | S5: - | T5: - | U5: - | V5: - | W5: - | X5: =IF(I5="","AG. FUNDIDO",IF(W5="OK","LIBERADA","EM USINAGEM")) -> AG. FUNDIDO
A6: 2284 | B6: 3 | C6: 212076 | D6: 3 | E6: Simisa | F6: RODETE MDA Z15 (BRUTO) | G6: 1 | H6: 46239 | J6: 46239 | L6: =Tabela13[[#This Row],[Data Prev. Entrega]]-TODAY() -> 9 | M6: =IF(L6<0,"ATRASADO",IF(L6<=15,"ATENÇÃO","NO PRAZO")) -> ATENÇÃO | N6: Bruto | O6: - | P6: - | Q6: - | R6: - | S6: - | T6: - | U6: - | V6: - | W6: - | X6: =IF(I6="","AG. FUNDIDO",IF(W6="OK","LIBERADA","EM USINAGEM")) -> AG. FUNDIDO
A7: 2284 | B7: 4 | C7: 212077 | D7: 1 | E7: Simisa | F7: RODETE MDA Z15 (BRUTO) | G7: 1 | H7: 46295 | J7: 46295 | L7: =Tabela13[[#This Row],[Data Prev. Entrega]]-TODAY() -> 65 | M7: =IF(L7<0,"ATRASADO",IF(L7<=15,"ATENÇÃO","NO PRAZO")) -> NO PRAZO | N7: Bruto | O7: - | P7: - | Q7: - | R7: - | S7: - | T7: - | U7: - | V7: - | W7: - | X7: =IF(I7="","AG. FUNDIDO",IF(W7="OK","LIBERADA","EM USINAGEM")) -> AG. FUNDIDO
A8: 2284 | B8: 5 | C8: 212078 | D8: 1 | E8: Simisa | F8: RODETE MDA Z15 (BRUTO) | G8: 1 | H8: 46239 | J8: 46239 | L8: =Tabela13[[#This Row],[Data Prev. Entrega]]-TODAY() -> 9 | M8: =IF(L8<0,"ATRASADO",IF(L8<=15,"ATENÇÃO","NO PRAZO")) -> ATENÇÃO | N8: Bruto | O8: - | P8: - | Q8: - | R8: - | S8: - | T8: - | U8: - | V8: - | W8: - | X8: =IF(I8="","AG. FUNDIDO",IF(W8="OK","LIBERADA","EM USINAGEM")) -> AG. FUNDIDO
A9: 2284 | B9: 6 | C9: 212079 | D9: 1 | E9: Simisa | F9: RODETE MDA Z15 (BRUTO) | G9: 1 | H9: 46266 | J9: 46266 | L9: =Tabela13[[#This Row],[Data Prev. Entrega]]-TODAY() -> 36 | M9: =IF(L9<0,"ATRASADO",IF(L9<=15,"ATENÇÃO","NO PRAZO")) -> NO PRAZO | N9: Bruto | O9: - | P9: - | Q9: - | R9: - | S9: - | T9: - | U9: - | V9: - | W9: - | X9: =IF(I9="","AG. FUNDIDO",IF(W9="OK","LIBERADA","EM USINAGEM")) -> AG. FUNDIDO
A10: 2284 | B10: 7 | C10: 212078 | D10: 2 | E10: Simisa | F10: RODETE MDA Z15 (BRUTO) | G10: 1 | H10: 46266 | J10: 46266 | L10: =Tabela13[[#This Row],[Data Prev. Entrega]]-TODAY() -> 36 | M10: =IF(L10<0,"ATRASADO",IF(L10<=15,"ATENÇÃO","NO PRAZO")) -> NO PRAZO | N10: Bruto | O10: - | P10: - | Q10: - | R10: - | S10: - | T10: - | U10: - | V10: - | W10: - | X10: =IF(I10="","AG. FUNDIDO",IF(W10="OK","LIBERADA","EM USINAGEM")) -> AG. FUNDIDO
A11: 2284 | B11: 8 | C11: 212080 | D11: 1 | E11: Simisa | F11: RODETE MDA Z15 (BRUTO) | G11: 1 | H11: 46266 | J11: 46266 | L11: =Tabela13[[#This Row],[Data Prev. Entrega]]-TODAY() -> 36 | M11: =IF(L11<0,"ATRASADO",IF(L11<=15,"ATENÇÃO","NO PRAZO")) -> NO PRAZO | N11: Bruto | O11: - | P11: - | Q11: - | R11: - | S11: - | T11: - | U11: - | V11: - | W11: - | X11: =IF(I11="","AG. FUNDIDO",IF(W11="OK","LIBERADA","EM USINAGEM")) -> AG. FUNDIDO
A12: 2284 | B12: 9 | C12: 212080 | D12: 2 | E12: Simisa | F12: RODETE MDA Z15 (BRUTO) | G12: 1 | H12: 46266 | J12: 46266 | L12: =Tabela13[[#This Row],[Data Prev. Entrega]]-TODAY() -> 36 | M12: =IF(L12<0,"ATRASADO",IF(L12<=15,"ATENÇÃO","NO PRAZO")) -> NO PRAZO | N12: Bruto | O12: - | P12: - | Q12: - | R12: - | S12: - | T12: - | U12: - | V12: - | W12: - | X12: =IF(I12="","AG. FUNDIDO",IF(W12="OK","LIBERADA","EM USINAGEM")) -> AG. FUNDIDO
A13: 2284 | B13: 10 | C13: 212080 | D13: 3 | E13: Simisa | F13: RODETE MDA Z15 (BRUTO) | G13: 1 | H13: 46266 | J13: 46266 | L13: =Tabela13[[#This Row],[Data Prev. Entrega]]-TODAY() -> 36 | M13: =IF(L13<0,"ATRASADO",IF(L13<=15,"ATENÇÃO","NO PRAZO")) -> NO PRAZO | N13: Bruto | O13: - | P13: - | Q13: - | R13: - | S13: - | T13: - | U13: - | V13: - | W13: - | X13: =IF(I13="","AG. FUNDIDO",IF(W13="OK","LIBERADA","EM USINAGEM")) -> AG. FUNDIDO
... A16: 2284 | B16: 13 | C16: 212080 | D16: 6 | E16: Simisa | F16: RODETE MDA Z15 (BRUTO) | G16: 1 | H16: 46295 | J16: 46295 | L16: =Tabela13[[#This Row],[Data Prev. Entrega]]-TODAY() -> 65 | M16: =IF(L16<0,"ATRASADO",IF(L16<=15,"ATENÇÃO","NO PRAZO")) -> NO PRAZO | N16: Bruto | O16: - | P16: - | Q16: - | R16: - | S16: - | T16: - | U16: - | V16: - | W16: - | X16: =IF(I16="","AG. FUNDIDO",IF(W16="OK","LIBERADA","EM USINAGEM")) -> AG. FUNDIDO
A17: 2320 | B17: 1 | C17: 1127009 | D17: 1 | E17: São João Araras | F17: RODETE PRESSÃO Z20 - 78" | G17: 1 | H17: 46249 | J17: 46280 | L17: =Tabela13[[#This Row],[Data Prev. Entrega]]-TODAY() -> 50 | M17: =IF(L17<0,"ATRASADO",IF(L17<=15,"ATENÇÃO","NO PRAZO")) -> NO PRAZO | N17: c/ usinagem | O17: =Tabela13[[#This Row],[Data Prev. Fundido]]-10 -> 46239 | P17: AG | Q17: Desb | R17: Envia T.T. | S17: Retorno T.T. | T17: Torno | U17: F. Dente | V17: Acab. | W17: Insp. | X17: =IF(I17="","AG. FUNDIDO",IF(W17="OK","LIBERADA","EM USINAGEM")) -> AG. FUNDIDO
A18: 2320 | B18: 2 | C18: 1127003 | D18: 11 | E18: São João Araras | F18: RODETE PRESSÃO Z15 - 84" | G18: 1 | H18: 46249 | J18: 46280 | L18: =Tabela13[[#This Row],[Data Prev. Entrega]]-TODAY() -> 50 | M18: =IF(L18<0,"ATRASADO",IF(L18<=15,"ATENÇÃO","NO PRAZO")) -> NO PRAZO | N18: c/ usinagem | O18: =Tabela13[[#This Row],[Data Prev. Fundido]]-10 -> 46239 | P18: AG | Q18: Desb | R18: Envia T.T. | S18: Retorno T.T. | T18: Torno | U18: F. Dente | V18: Acab. | W18: Insp. | X18: =IF(I18="","AG. FUNDIDO",IF(W18="OK","LIBERADA","EM USINAGEM")) -> AG. FUNDIDO
A19: 2320 | B19: 3 | C19: 1127003 | D19: 12 | E19: São João Araras | F19: RODETE MOENDA Z15 - 84" | G19: 1 | H19: 46249 | J19: 46280 | L19: =Tabela13[[#This Row],[Data Prev. Entrega]]-TODAY() -> 50 | M19: =IF(L19<0,"ATRASADO",IF(L19<=15,"ATENÇÃO","NO PRAZO")) -> NO PRAZO | N19: c/ usinagem | O19: =Tabela13[[#This Row],[Data Prev. Fundido]]-10 -> 46239 | P19: AG | Q19: Desb | R19: Envia T.T. | S19: Retorno T.T. | T19: Torno | U19: F. Dente | V19: Acab. | W19: Insp. | X19: =IF(I19="","AG. FUNDIDO",IF(W19="OK","LIBERADA","EM USINAGEM")) -> AG. FUNDIDO
A20: 2320 | B20: 4 | C20: 1127003 | D20: 13 | E20: São João Araras | F20: RODETE MOENDA Z15 - 84" | G20: 1 | H20: 46249 | J20: 46280 | L20: =Tabela13[[#This Row],[Data Prev. Entrega]]-TODAY() -> 50 | M20: =IF(L20<0,"ATRASADO",IF(L20<=15,"ATENÇÃO","NO PRAZO")) -> NO PRAZO | N20: c/ usinagem | O20: =Tabela13[[#This Row],[Data Prev. Fundido]]-10 -> 46239 | P20: AG | Q20: Desb | R20: Envia T.T. | S20: Retorno T.T. | T20: Torno | U20: F. Dente | V20: Acab. | W20: Insp. | X20: =IF(I20="","AG. FUNDIDO",IF(W20="OK","LIBERADA","EM USINAGEM")) -> AG. FUNDIDO
A21: 2320 | B21: 5 | C21: 1127005 | D21: 12 | E21: São João Araras | F21: RODETE MOENDA Z15 - 84" | G21: 1 | H21: 46249 | J21: 46280 | L21: =Tabela13[[#This Row],[Data Prev. Entrega]]-TODAY() -> 50 | M21: =IF(L21<0,"ATRASADO",IF(L21<=15,"ATENÇÃO","NO PRAZO")) -> NO PRAZO | N21: c/ usinagem | O21: =Tabela13[[#This Row],[Data Prev. Fundido]]-10 -> 46239 | P21: AG | Q21: Desb | R21: Envia T.T. | S21: Retorno T.T. | T21: Torno | U21: F. Dente | V21: Acab. | W21: Insp. | X21: =IF(I21="","AG. FUNDIDO",IF(W21="OK","LIBERADA","EM USINAGEM")) -> AG. FUNDIDO
A22: 2320 | B22: 6 | C22: 1127005 | D22: 13 | E22: São João Araras | F22: RODETE MOENDA Z15 - 84" | G22: 1 | H22: 46249 | J22: 46280 | L22: =Tabela13[[#This Row],[Data Prev. Entrega]]-TODAY() -> 50 | M22: =IF(L22<0,"ATRASADO",IF(L22<=15,"ATENÇÃO","NO PRAZO")) -> NO PRAZO | N22: c/ usinagem | O22: =Tabela13[[#This Row],[Data Prev. Fundido]]-10 -> 46239 | P22: AG | Q22: Desb | R22: Envia T.T. | S22: Retorno T.T. | T22: Torno | U22: F. Dente | V22: Acab. | W22: Insp. | X22: =IF(I22="","AG. FUNDIDO",IF(W22="OK","LIBERADA","EM USINAGEM")) -> AG. FUNDIDO
A23: 2320 | B23: 7 | C23: 1127005 | D23: 14 | E23: São João Araras | F23: RODETE MOENDA Z15 - 84" | G23: 1 | H23: 46249 | J23: 46280 | L23: =Tabela13[[#This Row],[Data Prev. Entrega]]-TODAY() -> 50 | M23: =IF(L23<0,"ATRASADO",IF(L23<=15,"ATENÇÃO","NO PRAZO")) -> NO PRAZO | N23: c/ usinagem | O23: =Tabela13[[#This Row],[Data Prev. Fundido]]-10 -> 46239 | P23: AG | Q23: Desb | R23: Envia T.T. | S23: Retorno T.T. | T23: Torno | U23: F. Dente | V23: Acab. | W23: Insp. | X23: =IF(I23="","AG. FUNDIDO",IF(W23="OK","LIBERADA","EM USINAGEM")) -> AG. FUNDIDO
A24: 2320 | B24: 8 | C24: 1127016 | D24: 1 | E24: São João Araras | F24: RODETE PRESSÃO Z20 - 84" | G24: 1 | H24: 46249 | J24: 46280 | L24: =Tabela13[[#This Row],[Data Prev. Entrega]]-TODAY() -> 50 | M24: =IF(L24<0,"ATRASADO",IF(L24<=15,"ATENÇÃO","NO PRAZO")) -> NO PRAZO | N24: c/ usinagem | O24: =Tabela13[[#This Row],[Data Prev. Fundido]]-10 -> 46239 | P24: AG | Q24: Desb | R24: Envia T.T. | S24: Retorno T.T. | T24: Torno | U24: F. Dente | V24: Acab. | W24: Insp. | X24: =IF(I24="","AG. FUNDIDO",IF(W24="OK","LIBERADA","EM USINAGEM")) -> AG. FUNDIDO
A25: 2320 | B25: 9 | C25: 1127017 | D25: 1 | E25: São João Araras | F25: RODETE PRESSÃO Z15 - 84" | G25: 1 | H25: 46249 | J25: 46280 | L25: =Tabela13[[#This Row],[Data Prev. Entrega]]-TODAY() -> 50 | M25: =IF(L25<0,"ATRASADO",IF(L25<=15,"ATENÇÃO","NO PRAZO")) -> NO PRAZO | N25: c/ usinagem | O25: =Tabela13[[#This Row],[Data Prev. Fundido]]-10 -> 46239 | P25: AG | Q25: Desb | R25: Envia T.T. | S25: Retorno T.T. | T25: Torno | U25: F. Dente | V25: Acab. | W25: Insp. | X25: =IF(I25="","AG. FUNDIDO",IF(W25="OK","LIBERADA","EM USINAGEM")) -> AG. FUNDIDO
A26: 1027 | B26: 7 | C26: 464100 | D26: - | E26: Água Bonita | F26: RODETE MOENDA Z15 - 1700 | G26: 1 | H26: 46315 | J26: 46374 | L26: =Tabela13[[#This Row],[Data Prev. Entrega]]-TODAY() -> 144 | M26: =IF(L26<0,"ATRASADO",IF(L26<=15,"ATENÇÃO","NO PRAZO")) -> NO PRAZO | N26: c/ usinagem | O26: OK | P26: AG | Q26: Desb | R26: Envia T.T. | S26: Retorno T.T. | T26: Torno | U26: F. Dente | V26: Acab. | W26: Insp. | X26: =IF(I26="","AG. FUNDIDO",IF(W26="OK","LIBERADA","EM USINAGEM")) -> AG. FUNDIDO
A27: 1027 | B27: 8 | C27: 464100 | D27: - | E27: Água Bonita | F27: RODETE MOENDA Z15 - 1700 | G27: 1 | H27: 46315 | J27: 46374 | L27: =Tabela13[[#This Row],[Data Prev. Entrega]]-TODAY() -> 144 | M27: =IF(L27<0,"ATRASADO",IF(L27<=15,"ATENÇÃO","NO PRAZO")) -> NO PRAZO | N27: c/ usinagem | O27: OK | P27: AG | Q27: Desb | R27: Envia T.T. | S27: Retorno T.T. | T27: Torno | U27: F. Dente | V27: Acab. | W27: Insp. | X27: =IF(I27="","AG. FUNDIDO",IF(W27="OK","LIBERADA","EM USINAGEM")) -> AG. FUNDIDO
A28: 1027 | B28: 9 | C28: 464100 | D28: - | E28: Água Bonita | F28: RODETE MOENDA Z15 - 1700 | G28: 1 | H28: 46315 | J28: 46374 | L28: =Tabela13[[#This Row],[Data Prev. Entrega]]-TODAY() -> 144 | M28: =IF(L28<0,"ATRASADO",IF(L28<=15,"ATENÇÃO","NO PRAZO")) -> NO PRAZO | N28: c/ usinagem | O28: OK | P28: AG | Q28: Desb | R28: Envia T.T. | S28: Retorno T.T. | T28: Torno | U28: F. Dente | V28: Acab. | W28: Insp. | X28: =IF(I28="","AG. FUNDIDO",IF(W28="OK","LIBERADA","EM USINAGEM")) -> AG. FUNDIDO
A29: 2329 | B29: 1 | C29: 187095 | D29: - | E29: São Domingos | F29: RODETE MOENDA Z15 - 78" | G29: 1 | H29: 46256 | J29: 46286 | L29: =Tabela13[[#This Row],[Data Prev. Entrega]]-TODAY() -> 56 | M29: =IF(L29<0,"ATRASADO",IF(L29<=15,"ATENÇÃO","NO PRAZO")) -> NO PRAZO | N29: c/ usinagem | O29: =Tabela13[[#This Row],[Data Prev. Fundido]]-10 -> 46246 | P29: AG | Q29: Desb | R29: Envia T.T. | S29: Retorno T.T. | T29: Torno | U29: F. Dente | V29: Acab. | W29: Insp. | X29: =IF(I29="","AG. FUNDIDO",IF(W29="OK","LIBERADA","EM USINAGEM")) -> AG. FUNDIDO
A30: 2329 | B30: 2 | C30: 187095 | D30: - | E30: São Domingos | F30: RODETE MOENDA Z15 - 78" | G30: 1 | H30: 46256 | J30: 46286 | L30: =Tabela13[[#This Row],[Data Prev. Entrega]]-TODAY() -> 56 | M30: =IF(L30<0,"ATRASADO",IF(L30<=15,"ATENÇÃO","NO PRAZO")) -> NO PRAZO | N30: c/ usinagem | O30: =Tabela13[[#This Row],[Data Prev. Fundido]]-10 -> 46246 | P30: AG | Q30: Desb | R30: Envia T.T. | S30: Retorno T.T. | T30: Torno | U30: F. Dente | V30: Acab. | W30: Insp. | X30: =IF(I30="","AG. FUNDIDO",IF(W30="OK","LIBERADA","EM USINAGEM")) -> AG. FUNDIDO
A31: 2329 | B31: 3 | C31: 187095 | D31: - | E31: São Domingos | F31: RODETE MOENDA Z15 - 78" | G31: 1 | H31: 46256 | J31: 46286 | L31: =Tabela13[[#This Row],[Data Prev. Entrega]]-TODAY() -> 56 | M31: =IF(L31<0,"ATRASADO",IF(L31<=15,"ATENÇÃO","NO PRAZO")) -> NO PRAZO | N31: c/ usinagem | O31: =Tabela13[[#This Row],[Data Prev. Fundido]]-10 -> 46246 | P31: AG | Q31: Desb | R31: Envia T.T. | S31: Retorno T.T. | T31: Torno | U31: F. Dente | V31: Acab. | W31: Insp. | X31: =IF(I31="","AG. FUNDIDO",IF(W31="OK","LIBERADA","EM USINAGEM")) -> AG. FUNDIDO
A32: 2331 | B32: 8 | C32: 27611 | D32: 8 | E32: Lins Agroindustrial | F32: RODETE MOENDA Z15 - 78" | G32: 1 | H32: 46315 | J32: 46374 | L32: =Tabela13[[#This Row],[Data Prev. Entrega]]-TODAY() -> 144 | M32: =IF(L32<0,"ATRASADO",IF(L32<=15,"ATENÇÃO","NO PRAZO")) -> NO PRAZO | N32: c/ usinagem | O32: =Tabela13[[#This Row],[Data Prev. Fundido]]-10 -> 46305 | P32: AG | Q32: Desb | R32: Envia T.T. | S32: Retorno T.T. | T32: Torno | U32: F. Dente | V32: Acab. | W32: Insp. | X32: =IF(I32="","AG. FUNDIDO",IF(W32="OK","LIBERADA","EM USINAGEM")) -> AG. FUNDIDO
A33: 2331 | B33: 9 | C33: 27611 | D33: 9 | E33: Lins Agroindustrial | F33: RODETE MOENDA Z15 - 78" | G33: 1 | H33: 46315 | J33: 46374 | L33: =Tabela13[[#This Row],[Data Prev. Entrega]]-TODAY() -> 144 | M33: =IF(L33<0,"ATRASADO",IF(L33<=15,"ATENÇÃO","NO PRAZO")) -> NO PRAZO | N33: c/ usinagem | O33: =Tabela13[[#This Row],[Data Prev. Fundido]]-10 -> 46305 | P33: AG | Q33: Desb | R33: Envia T.T. | S33: Retorno T.T. | T33: Torno | U33: F. Dente | V33: Acab. | W33: Insp. | X33: =IF(I33="","AG. FUNDIDO",IF(W33="OK","LIBERADA","EM USINAGEM")) -> AG. FUNDIDO
A34: 2331 | B34: 10 | C34: 27611 | D34: 10 | E34: Lins Agroindustrial | F34: RODETE PRESSÃO Z15 - 78" | G34: 1 | H34: 46315 | J34: 46374 | L34: =Tabela13[[#This Row],[Data Prev. Entrega]]-TODAY() -> 144 | M34: =IF(L34<0,"ATRASADO",IF(L34<=15,"ATENÇÃO","NO PRAZO")) -> NO PRAZO | N34: c/ usinagem | O34: =Tabela13[[#This Row],[Data Prev. Fundido]]-10 -> 46305 | P34: AG | Q34: Desb | R34: Envia T.T. | S34: Retorno T.T. | T34: Torno | U34: F. Dente | V34: Acab. | W34: Insp. | X34: =IF(I34="","AG. FUNDIDO",IF(W34="OK","LIBERADA","EM USINAGEM")) -> AG. FUNDIDO
A35: 2331 | B35: 11 | C35: 27611 | D35: 11 | E35: Lins Agroindustrial | F35: RODETE PRESSÃO Z15 - 78" | G35: 1 | H35: 46315 | J35: 46374 | L35: =Tabela13[[#This Row],[Data Prev. Entrega]]-TODAY() -> 144 | M35: =IF(L35<0,"ATRASADO",IF(L35<=15,"ATENÇÃO","NO PRAZO")) -> NO PRAZO | N35: c/ usinagem | O35: =Tabela13[[#This Row],[Data Prev. Fundido]]-10 -> 46305 | P35: AG | Q35: Desb | R35: Envia T.T. | S35: Retorno T.T. | T35: Torno | U35: F. Dente | V35: Acab. | W35: Insp. | X35: =IF(I35="","AG. FUNDIDO",IF(W35="OK","LIBERADA","EM USINAGEM")) -> AG. FUNDIDO
A36: 2337 | B36: 1 | C36: 27620 | D36: 1 | E36: Colorado | F36: RODETE MOENDA Z15 - 66" | G36: 1 | H36: 46265 | J36: 46295 | L36: =Tabela13[[#This Row],[Data Prev. Entrega]]-TODAY() -> 65 | M36: =IF(L36<0,"ATRASADO",IF(L36<=15,"ATENÇÃO","NO PRAZO")) -> NO PRAZO | N36: c/ usinagem | O36: 46223 | P36: AG | Q36: Desb | R36: Envia T.T. | S36: Retorno T.T. | T36: Torno | U36: F. Dente | V36: Acab. | W36: Insp. | X36: =IF(I36="","AG. FUNDIDO",IF(W36="OK","LIBERADA","EM USINAGEM")) -> AG. FUNDIDO
A37: 2337 | B37: 2 | C37: 27620 | D37: 2 | E37: Colorado | F37: RODETE MOENDA Z15 - 90" | G37: 1 | H37: 46265 | J37: 46295 | L37: =Tabela13[[#This Row],[Data Prev. Entrega]]-TODAY() -> 65 | M37: =IF(L37<0,"ATRASADO",IF(L37<=15,"ATENÇÃO","NO PRAZO")) -> NO PRAZO | N37: c/ usinagem | O37: 46223 | P37: AG | Q37: Desb | R37: Envia T.T. | S37: Retorno T.T. | T37: Torno | U37: F. Dente | V37: Acab. | W37: Insp. | X37: =IF(I37="","AG. FUNDIDO",IF(W37="OK","LIBERADA","EM USINAGEM")) -> AG. FUNDIDO
A38: 2337 | B38: 3 | C38: 27620 | D38: 3 | E38: Colorado | F38: RODETE MOENDA Z15 - 78" | G38: 1 | H38: 46265 | J38: 46295 | L38: =Tabela13[[#This Row],[Data Prev. Entrega]]-TODAY() -> 65 | M38: =IF(L38<0,"ATRASADO",IF(L38<=15,"ATENÇÃO","NO PRAZO")) -> NO PRAZO | N38: c/ usinagem | O38: 46223 | P38: AG | Q38: Desb | R38: Envia T.T. | S38: Retorno T.T. | T38: Torno | U38: F. Dente | V38: Acab. | W38: Insp. | X38: =IF(I38="","AG. FUNDIDO",IF(W38="OK","LIBERADA","EM USINAGEM")) -> AG. FUNDIDO
A39: 2337 | B39: 4 | C39: 27620 | D39: 4 | E39: Colorado | F39: RODETE MOENDA Z15 - 78" | G39: 1 | H39: 46265 | J39: 46295 | L39: =Tabela13[[#This Row],[Data Prev. Entrega]]-TODAY() -> 65 | M39: =IF(L39<0,"ATRASADO",IF(L39<=15,"ATENÇÃO","NO PRAZO")) -> NO PRAZO | N39: c/ usinagem | O39: 46223 | P39: AG | Q39: Desb | R39: Envia T.T. | S39: Retorno T.T. | T39: Torno | U39: F. Dente | V39: Acab. | W39: Insp. | X39: =IF(I39="","AG. FUNDIDO",IF(W39="OK","LIBERADA","EM USINAGEM")) -> AG. FUNDIDO
A40: 2361 | B40: 1 | C40: 27656 | D40: 1 | E40: Guabira | F40: RODETE MOENDA Z16 - 54" | G40: 1 | H40: 46284 | J40: 46329 | L40: =Tabela13[[#This Row],[Data Prev. Entrega]]-TODAY() -> 99 | M40: =IF(L40<0,"ATRASADO",IF(L40<=15,"ATENÇÃO","NO PRAZO")) -> NO PRAZO | N40: c/ usinagem | O40: 46274 | P40: AG | Q40: Desb | R40: Envia T.T. | S40: Retorno T.T. | T40: Torno | U40: F. Dente | V40: Acab. | W40: Insp. | X40: =IF(I40="","AG. FUNDIDO",IF(W40="OK","LIBERADA","EM USINAGEM")) -> AG. FUNDIDO
A41: 2361 | B41: 2 | C41: 27656 | D41: 2 | E41: Guabira | F41: RODETE MOENDA Z16 - 54" | G41: 1 | H41: 46284 | J41: 46329 | L41: =Tabela13[[#This Row],[Data Prev. Entrega]]-TODAY() -> 99 | M41: =IF(L41<0,"ATRASADO",IF(L41<=15,"ATENÇÃO","NO PRAZO")) -> NO PRAZO | N41: c/ usinagem | O41: 46274 | P41: AG | Q41: Desb | R41: Envia T.T. | S41: Retorno T.T. | T41: Torno | U41: F. Dente | V41: Acab. | W41: Insp. | X41: =IF(I41="","AG. FUNDIDO",IF(W41="OK","LIBERADA","EM USINAGEM")) -> AG. FUNDIDO
A42: 2361 | B42: 3 | C42: 27656 | D42: 3 | E42: Guabira | F42: RODETE MOENDA Z16 - 54" | G42: 1 | H42: 46284 | J42: 46329 | L42: =Tabela13[[#This Row],[Data Prev. Entrega]]-TODAY() -> 99 | M42: =IF(L42<0,"ATRASADO",IF(L42<=15,"ATENÇÃO","NO PRAZO")) -> NO PRAZO | N42: c/ usinagem | O42: 46274 | P42: AG | Q42: Desb | R42: Envia T.T. | S42: Retorno T.T. | T42: Torno | U42: F. Dente | V42: Acab. | W42: Insp. | X42: =IF(I42="","AG. FUNDIDO",IF(W42="OK","LIBERADA","EM USINAGEM")) -> AG. FUNDIDO
...

Sheet REFORMA DIVERSAS
A1: PV | B1: Item | C1: Cliente | D1: Descrição | E1: Qtde. | F1: Bit | G1: Terno | H1: Desenho Previsão | I1: Des. | J1: Prazo Entrega | K1: OP1 | L1: OP2 | M1: OP3 | N1: OP4 | O1: OP5 | P1: OP6 | Q1: OP7 | R1: OP8 | S1: OP9 | T1: Status | U1: Observação
A2: 1027 | B2: - | C2: Água Bonita | D2: Manutenção Cabeçote Lateral | E2: 4 | F2: 66" | G2: 2º | H2: 46388 | I2: AG | J2: 46423 | K2: Receber | L2: Insp. | M2: Laudo | T2: AG. PEÇA CLIENTE
A3: 1027 | B3: - | C3: Água Bonita | D3: Manutenção Cabeçote Lateral | E3: 4 | F3: 66" | G3: 3º | H3: 46388 | I3: AG | J3: 46423 | K3: Receber | L3: Insp. | M3: Laudo | T3: AG. PEÇA CLIENTE
A4: 1027 | B4: - | C4: Água Bonita | D4: Manutenção Balança | E4: 1 | F4: 66" | G4: 3º | H4: 46388 | I4: AG | J4: 46414 | K4: Receber | L4: Insp. | M4: Laudo | T4: AG. PEÇA CLIENTE
A5: 1027 | B5: - | C5: Água Bonita | D5: Manutenção Caixa Mancal Inf | E5: 2 | F5: 66" | G5: 3º | H5: 46388 | I5: AG | J5: 46376 | K5: Receber | L5: Insp. | M5: Laudo | T5: AG. LAUDO
A6: 1027 | B6: - | C6: Água Bonita | D6: Manutenção Caixa Mancal Inf | E6: 2 | F6: 66" | G6: 3º | H6: 46388 | I6: AG | J6: 46407 | K6: Receber | L6: Insp. | M6: Laudo | T6: AG. PEÇA CLIENTE
A7: 1027 | B7: - | C7: Água Bonita | D7: Manutenção Caixa Mancal Inf | E7: 4 | F7: 66" | G7: 4º | H7: 46388 | I7: AG | J7: 46407 | K7: Receber | L7: Insp. | M7: Laudo | T7: AG. PEÇA CLIENTE
